{
 "cells": [
  {
   "cell_type": "markdown",
   "id": "464ec12f-f0aa-4601-b4a5-6d6c0eb43b0e",
   "metadata": {},
   "source": [
    "Q.1.What is an Exception in python?Write the difference between Exceptions and Syntax errors."
   ]
  },
  {
   "cell_type": "markdown",
   "id": "db2b22bf-828c-4638-bcee-547249648c54",
   "metadata": {},
   "source": [
    "Ans :- An exception is an event, which occurs during the execution of a program that disrupts the normal flow of the program's instructions. In general, when a Python script encounters a situation that it cannot cope with, it raises an exception. An exception is a Python object that represents an error.\n",
    "\n",
    "When a Python script raises an exception, it must either handle the exception immediately otherwise it terminates and quits.\n",
    "\n",
    "Syntax errors\n",
    "When the proper syntax of the language is not followed then a syntax error is thrown.\n",
    "\n",
    "Exception)\n",
    "When in the runtime an error that occurs after passing the syntax test is called exception or logical type. For example, when we divide any number by zero then the ZeroDivisionError exception is raised, or when we import a module that does not exist then ImportError is raised."
   ]
  },
  {
   "cell_type": "markdown",
   "id": "d9ae9ee7-a787-4875-af25-6aa61fd6e760",
   "metadata": {},
   "source": [
    "Q.2.What happens when an Exception is not handled? Explain with an Example."
   ]
  },
  {
   "cell_type": "markdown",
   "id": "fabed483-947f-400b-ac98-40cca9939f36",
   "metadata": {},
   "source": [
    "Ans:- Exceptions are errors that are detected during execution. Whenever there is an error in a program, exceptions are raised.\n",
    "\n",
    "If these exceptions are not handled, it drives the program into a halt state. Exception handling in python is required to prevent the program from terminating abruptly. "
   ]
  },
  {
   "cell_type": "code",
   "execution_count": 2,
   "id": "5ceae515-bec5-4768-b55f-63703a1c0762",
   "metadata": {},
   "outputs": [
    {
     "ename": "ZeroDivisionError",
     "evalue": "division by zero",
     "output_type": "error",
     "traceback": [
      "\u001b[0;31m---------------------------------------------------------------------------\u001b[0m",
      "\u001b[0;31mZeroDivisionError\u001b[0m                         Traceback (most recent call last)",
      "Cell \u001b[0;32mIn[2], line 3\u001b[0m\n\u001b[1;32m      1\u001b[0m a \u001b[38;5;241m=\u001b[39m \u001b[38;5;241m10\u001b[39m\n\u001b[1;32m      2\u001b[0m b \u001b[38;5;241m=\u001b[39m \u001b[38;5;241m0\u001b[39m\n\u001b[0;32m----> 3\u001b[0m c \u001b[38;5;241m=\u001b[39m \u001b[43ma\u001b[49m\u001b[38;5;241;43m/\u001b[39;49m\u001b[43mb\u001b[49m\n\u001b[1;32m      4\u001b[0m \u001b[38;5;28mprint\u001b[39m(c)\n",
      "\u001b[0;31mZeroDivisionError\u001b[0m: division by zero"
     ]
    }
   ],
   "source": [
    "a = 10\n",
    "b = 0\n",
    "c = a/b\n",
    "print(c)"
   ]
  },
  {
   "cell_type": "markdown",
   "id": "0354b15b-51aa-482d-a29d-15423aea682f",
   "metadata": {},
   "source": [
    "Above is an example of what we call an unhandled exception. On line 3, the code went into a halt state as it's an unhandled exception."
   ]
  },
  {
   "cell_type": "markdown",
   "id": "33dff000-27ec-49d6-ab3e-0cec0d158e2c",
   "metadata": {},
   "source": [
    "Q.3.Which python statements are used to catch and handle exceptions?Explain with an example."
   ]
  },
  {
   "cell_type": "markdown",
   "id": "d1c0f04d-da04-487d-9464-baad954156c6",
   "metadata": {},
   "source": [
    "Ans:-The try and except block in Python is used to catch and handle exceptions. Python executes code following the try statement as a “normal” part of the program. The code that follows the except statement is the program's response to any exceptions in the preceding try clause."
   ]
  },
  {
   "cell_type": "code",
   "execution_count": 3,
   "id": "92f252c0-0742-4488-811f-8b5ef9aff5e5",
   "metadata": {},
   "outputs": [
    {
     "name": "stdout",
     "output_type": "stream",
     "text": [
      "The index and element from the array is 0 Python\n",
      "The index and element from the array is 1 Exceptions\n",
      "The index and element from the array is 2 try and except\n",
      "Index out of range\n"
     ]
    }
   ],
   "source": [
    "# Python code to catch an exception and handle it using try and except code blocks  \n",
    "   \n",
    "a = [\"Python\", \"Exceptions\", \"try and except\"]  \n",
    "try:  \n",
    "    #looping through the elements of the array a, choosing a range that goes beyond the length of the array  \n",
    "     for i in range( 4 ):  \n",
    "        print( \"The index and element from the array is\", i, a[i] )  \n",
    "#if an error occurs in the try block, then except block will be executed by the Python interpreter       \n",
    "except:  \n",
    "    print (\"Index out of range\")  "
   ]
  },
  {
   "cell_type": "markdown",
   "id": "af7acc6b-4bfc-47d1-8d04-39c0c8f9ecc2",
   "metadata": {},
   "source": [
    "Q.4.Explain with an example :-\n",
    "a.try and else\n",
    "b.finally\n",
    "c.raise"
   ]
  },
  {
   "cell_type": "markdown",
   "id": "85d3a7e4-38dd-411d-891c-15c824ca4bda",
   "metadata": {},
   "source": [
    "Ans:- a. try and else :-\n",
    "The try block test a block of code for errors. The except block handle the error. The else block execute code when there is no error."
   ]
  },
  {
   "cell_type": "code",
   "execution_count": 4,
   "id": "62c30079-fe77-4408-9e22-497e4b12e0b6",
   "metadata": {},
   "outputs": [
    {
     "name": "stdout",
     "output_type": "stream",
     "text": [
      "Hello\n",
      "Nothing went wrong\n"
     ]
    }
   ],
   "source": [
    "try:\n",
    "  print(\"Hello\")\n",
    "except:\n",
    "  print(\"Something went wrong\")\n",
    "else:\n",
    "  print(\"Nothing went wrong\")"
   ]
  },
  {
   "cell_type": "markdown",
   "id": "c35b5e71-f903-4922-807f-5c6061a27132",
   "metadata": {},
   "source": [
    "b.finally:- The finally keyword is used in try...except blocks. It defines a block of code to run when the try...except...else block is final.\n",
    "\n",
    "The finally block will be executed no matter if the try block raises an error or not."
   ]
  },
  {
   "cell_type": "code",
   "execution_count": 5,
   "id": "a95f5f96-4072-444d-a5ac-2d0e660a8f64",
   "metadata": {},
   "outputs": [
    {
     "name": "stdout",
     "output_type": "stream",
     "text": [
      "finally will execute itself in any situation \n"
     ]
    },
    {
     "ename": "FileNotFoundError",
     "evalue": "[Errno 2] No such file or directory: 'test4.txt'",
     "output_type": "error",
     "traceback": [
      "\u001b[0;31m---------------------------------------------------------------------------\u001b[0m",
      "\u001b[0;31mFileNotFoundError\u001b[0m                         Traceback (most recent call last)",
      "Cell \u001b[0;32mIn[5], line 2\u001b[0m\n\u001b[1;32m      1\u001b[0m \u001b[38;5;28;01mtry\u001b[39;00m :\n\u001b[0;32m----> 2\u001b[0m     f \u001b[38;5;241m=\u001b[39m \u001b[38;5;28;43mopen\u001b[39;49m\u001b[43m(\u001b[49m\u001b[38;5;124;43m\"\u001b[39;49m\u001b[38;5;124;43mtest4.txt\u001b[39;49m\u001b[38;5;124;43m\"\u001b[39;49m\u001b[43m,\u001b[49m\u001b[43m \u001b[49m\u001b[38;5;124;43m\"\u001b[39;49m\u001b[38;5;124;43mr\u001b[39;49m\u001b[38;5;124;43m\"\u001b[39;49m\u001b[43m)\u001b[49m\n\u001b[1;32m      3\u001b[0m     f\u001b[38;5;241m.\u001b[39mwrite(\u001b[38;5;124m\"\u001b[39m\u001b[38;5;124m this is shubham \u001b[39m\u001b[38;5;124m\"\u001b[39m)\n\u001b[1;32m      5\u001b[0m \u001b[38;5;28;01mfinally\u001b[39;00m :\n",
      "File \u001b[0;32m/opt/conda/lib/python3.10/site-packages/IPython/core/interactiveshell.py:282\u001b[0m, in \u001b[0;36m_modified_open\u001b[0;34m(file, *args, **kwargs)\u001b[0m\n\u001b[1;32m    275\u001b[0m \u001b[38;5;28;01mif\u001b[39;00m file \u001b[38;5;129;01min\u001b[39;00m {\u001b[38;5;241m0\u001b[39m, \u001b[38;5;241m1\u001b[39m, \u001b[38;5;241m2\u001b[39m}:\n\u001b[1;32m    276\u001b[0m     \u001b[38;5;28;01mraise\u001b[39;00m \u001b[38;5;167;01mValueError\u001b[39;00m(\n\u001b[1;32m    277\u001b[0m         \u001b[38;5;124mf\u001b[39m\u001b[38;5;124m\"\u001b[39m\u001b[38;5;124mIPython won\u001b[39m\u001b[38;5;124m'\u001b[39m\u001b[38;5;124mt let you open fd=\u001b[39m\u001b[38;5;132;01m{\u001b[39;00mfile\u001b[38;5;132;01m}\u001b[39;00m\u001b[38;5;124m by default \u001b[39m\u001b[38;5;124m\"\u001b[39m\n\u001b[1;32m    278\u001b[0m         \u001b[38;5;124m\"\u001b[39m\u001b[38;5;124mas it is likely to crash IPython. If you know what you are doing, \u001b[39m\u001b[38;5;124m\"\u001b[39m\n\u001b[1;32m    279\u001b[0m         \u001b[38;5;124m\"\u001b[39m\u001b[38;5;124myou can use builtins\u001b[39m\u001b[38;5;124m'\u001b[39m\u001b[38;5;124m open.\u001b[39m\u001b[38;5;124m\"\u001b[39m\n\u001b[1;32m    280\u001b[0m     )\n\u001b[0;32m--> 282\u001b[0m \u001b[38;5;28;01mreturn\u001b[39;00m \u001b[43mio_open\u001b[49m\u001b[43m(\u001b[49m\u001b[43mfile\u001b[49m\u001b[43m,\u001b[49m\u001b[43m \u001b[49m\u001b[38;5;241;43m*\u001b[39;49m\u001b[43margs\u001b[49m\u001b[43m,\u001b[49m\u001b[43m \u001b[49m\u001b[38;5;241;43m*\u001b[39;49m\u001b[38;5;241;43m*\u001b[39;49m\u001b[43mkwargs\u001b[49m\u001b[43m)\u001b[49m\n",
      "\u001b[0;31mFileNotFoundError\u001b[0m: [Errno 2] No such file or directory: 'test4.txt'"
     ]
    }
   ],
   "source": [
    "try :\n",
    "    f = open(\"test4.txt\", \"r\")\n",
    "    f.write(\" this is shubham \")\n",
    "    \n",
    "finally :\n",
    "    print(\"finally will execute itself in any situation \")\n",
    "    "
   ]
  },
  {
   "cell_type": "markdown",
   "id": "4d791172-1743-4752-ab84-e01c46cb33ed",
   "metadata": {},
   "source": [
    "c.raise:-The raise keyword is used to raise an exception. You can define what kind of error to raise, and the text to print to the user."
   ]
  },
  {
   "cell_type": "code",
   "execution_count": 7,
   "id": "e306b104-0324-4f5b-94ea-bf3adf37d108",
   "metadata": {},
   "outputs": [
    {
     "ename": "Exception",
     "evalue": "Sorry, no numbers below zero",
     "output_type": "error",
     "traceback": [
      "\u001b[0;31m---------------------------------------------------------------------------\u001b[0m",
      "\u001b[0;31mException\u001b[0m                                 Traceback (most recent call last)",
      "Cell \u001b[0;32mIn[7], line 4\u001b[0m\n\u001b[1;32m      1\u001b[0m x \u001b[38;5;241m=\u001b[39m \u001b[38;5;241m-\u001b[39m\u001b[38;5;241m1\u001b[39m\n\u001b[1;32m      3\u001b[0m \u001b[38;5;28;01mif\u001b[39;00m x \u001b[38;5;241m<\u001b[39m \u001b[38;5;241m0\u001b[39m:\n\u001b[0;32m----> 4\u001b[0m   \u001b[38;5;28;01mraise\u001b[39;00m \u001b[38;5;167;01mException\u001b[39;00m(\u001b[38;5;124m\"\u001b[39m\u001b[38;5;124mSorry, no numbers below zero\u001b[39m\u001b[38;5;124m\"\u001b[39m)\n",
      "\u001b[0;31mException\u001b[0m: Sorry, no numbers below zero"
     ]
    }
   ],
   "source": [
    "x = -1\n",
    "\n",
    "if x < 0:\n",
    "  raise Exception(\"Sorry, no numbers below zero\")\n"
   ]
  },
  {
   "cell_type": "markdown",
   "id": "4467ed90-fe4a-419e-9606-0f3ff05f68fe",
   "metadata": {},
   "source": [
    "Q.5.What are Custom Exceptions in python?Why do we need custom Exceptions?Explain with an Example."
   ]
  },
  {
   "cell_type": "markdown",
   "id": "baf9526f-86b0-424b-80a4-a01c9b1a14cf",
   "metadata": {},
   "source": [
    "Ans:\"- Custom exceptions are user defined exceptions in python.Sometimes based on project requirement, a programmer needs to create his own exceptions and raise explicitly for corresponding scenarios. Such types of exceptions are called customized Exceptions or Programmatic Exceptions. We can raise a custom exception by using the keyword ‘raise’."
   ]
  },
  {
   "cell_type": "code",
   "execution_count": 9,
   "id": "02d7f60a-67a8-4528-9c14-1edc0a23c9ad",
   "metadata": {},
   "outputs": [
    {
     "name": "stdin",
     "output_type": "stream",
     "text": [
      "Enter a number between positive integer:  -32\n"
     ]
    },
    {
     "name": "stdout",
     "output_type": "stream",
     "text": [
      "You provided -32. Please provide positive integer values only\n"
     ]
    }
   ],
   "source": [
    "class NegativeError(Exception):\n",
    "   def __init__(self, data):\n",
    "       self.data = data\n",
    "try:\n",
    "   x = int(input(\"Enter a number between positive integer: \"))\n",
    "   if x < 0:\n",
    "       raise NegativeError(x)\n",
    "except NegativeError as e:\n",
    "   print(\"You provided {}. Please provide positive integer values only\".format(e))\n"
   ]
  },
  {
   "cell_type": "markdown",
   "id": "a4650c81-f028-4710-9883-ab494900a3db",
   "metadata": {},
   "source": [
    "Q.6.Create a custom exception class.use this class to handle an exception."
   ]
  },
  {
   "cell_type": "code",
   "execution_count": 14,
   "id": "4ea47368-5310-4d7b-9987-cc25252a3b9c",
   "metadata": {},
   "outputs": [
    {
     "name": "stdin",
     "output_type": "stream",
     "text": [
      "Enter Age: 65\n"
     ]
    },
    {
     "ename": "TooOldException",
     "evalue": "Your age already crossed marriage age...no chance of getting marriage",
     "output_type": "error",
     "traceback": [
      "\u001b[0;31m---------------------------------------------------------------------------\u001b[0m",
      "\u001b[0;31mTooOldException\u001b[0m                           Traceback (most recent call last)",
      "Cell \u001b[0;32mIn[14], line 9\u001b[0m\n\u001b[1;32m      7\u001b[0m age\u001b[38;5;241m=\u001b[39m\u001b[38;5;28mint\u001b[39m(\u001b[38;5;28minput\u001b[39m(\u001b[38;5;124m\"\u001b[39m\u001b[38;5;124mEnter Age:\u001b[39m\u001b[38;5;124m\"\u001b[39m))\n\u001b[1;32m      8\u001b[0m \u001b[38;5;28;01mif\u001b[39;00m age\u001b[38;5;241m>\u001b[39m\u001b[38;5;241m60\u001b[39m:\n\u001b[0;32m----> 9\u001b[0m    \u001b[38;5;28;01mraise\u001b[39;00m TooOldException(\u001b[38;5;124m\"\u001b[39m\u001b[38;5;124mYour age already crossed marriage age...no chance of getting marriage\u001b[39m\u001b[38;5;124m\"\u001b[39m)\n\u001b[1;32m     10\u001b[0m \u001b[38;5;28;01melif\u001b[39;00m age\u001b[38;5;241m<\u001b[39m\u001b[38;5;241m18\u001b[39m:\n\u001b[1;32m     11\u001b[0m    \u001b[38;5;28;01mraise\u001b[39;00m TooYoungException(\u001b[38;5;124m\"\u001b[39m\u001b[38;5;124mPlz wait some more time you will get best match soon!!!\u001b[39m\u001b[38;5;124m\"\u001b[39m)\n",
      "\u001b[0;31mTooOldException\u001b[0m: Your age already crossed marriage age...no chance of getting marriage"
     ]
    }
   ],
   "source": [
    "class TooYoungException(Exception):\n",
    "   def __init__(self, arg):\n",
    "       self.msg=arg\n",
    "class TooOldException(Exception):\n",
    "   def __init__(self, arg):\n",
    "       self.msg=arg\n",
    "age=int(input(\"Enter Age:\"))\n",
    "if age>60:\n",
    "   raise TooOldException(\"Your age already crossed marriage age...no chance of getting marriage\")\n",
    "elif age<18:\n",
    "   raise TooYoungException(\"Plz wait some more time you will get best match soon!!!\")\n",
    "else:\n",
    "   print(\"You will get match details soon by email!!!\")\n"
   ]
  },
  {
   "cell_type": "code",
   "execution_count": null,
   "id": "6eb4a531-e583-4211-9d21-11b4c543982a",
   "metadata": {},
   "outputs": [],
   "source": []
  }
 ],
 "metadata": {
  "kernelspec": {
   "display_name": "Python 3 (ipykernel)",
   "language": "python",
   "name": "python3"
  },
  "language_info": {
   "codemirror_mode": {
    "name": "ipython",
    "version": 3
   },
   "file_extension": ".py",
   "mimetype": "text/x-python",
   "name": "python",
   "nbconvert_exporter": "python",
   "pygments_lexer": "ipython3",
   "version": "3.10.8"
  }
 },
 "nbformat": 4,
 "nbformat_minor": 5
}
